Workbook

Sheet Formulario de Ingreso
B2: APLICATIVO DE REGISTRO CONTABLE
B3: FORMULARIO DE INGRESO (INTERFAZ TIPO APP)
B4: Complete los campos amarillos y presione el botón REGISTRAR. El registro se guardará automáticamente en 'Base de Datos' y en el 'Libro Diario' (requiere la macro indicada en la hoja Instrucciones).
B6: Cuenta contable (Código): | D6: =IF(C6="","",IFERROR(INDEX('Plan de Cuentas'!$B$5:$B$1241,MATCH(C6,'Plan de Cuentas'!$A$5:$A$1241,0)),"Código no encontrado"))
B7: Contra-cuenta (con la que hace match / cuadra): | D7: =IF(C7="","",IFERROR(INDEX('Plan de Cuentas'!$B$5:$B$1241,MATCH(C7,'Plan de Cuentas'!$A$5:$A$1241,0)),"Código no encontrado"))
B8: Monto (S/):
B9: Observación:
B10: Tipo de movimiento (¿la cuenta principal es Ingreso o Salida?):
B12: ▶ REGISTRAR INGRESO
B15: Este recuadro es el botón visual. Para que quede clicable de verdad y registre el dato automáticamente, asígnele la macro 'RegistrarIngreso' (ver hoja 'Instrucciones Macro'). Es un procedimiento de 2 minutos, una sola vez.

Sheet Base de Datos
A1: BASE DE DATOS DE REGISTROS (histórico infinito)
A2: Cada fila es un registro hecho desde 'Formulario de Ingreso'. Con la macro instalada se completa solo; también puede escribir aquí directamente si no usa la macro. Estos mismos datos deben reflejarse como asiento (Debe/Haber) en el Libro Diario para que el valor contable cuadre.
A4: N° | B4: Fecha | C4: Hora | D4: Código Cuenta | E4: Denominación Cuenta | F4: Código Contra-cuenta | G4: Denominación Contra-cuenta | H4: Monto (S/) | I4: Observación
A5: 1 | B5: 46024 | C5: 0.375 | D5: 101 | E5: =IFERROR(INDEX('Plan de Cuentas'!$B$5:$B$1241,MATCH(D5,'Plan de Cuentas'!$A$5:$A$1241,0)),"") -> Caja | F5: 5011 | G5: =IFERROR(INDEX('Plan de Cuentas'!$B$5:$B$1241,MATCH(F5,'Plan de Cuentas'!$A$5:$A$1241,0)),"") -> Acciones | H5: 10 | I5: Aporte de capital en efectivo (ejemplo)
E6: =IF(D6="","",IFERROR(INDEX('Plan de Cuentas'!$B$5:$B$1241,MATCH(D6,'Plan de Cuentas'!$A$5:$A$1241,0)),"No encontrado")) | G6: =IF(F6="","",IFERROR(INDEX('Plan de Cuentas'!$B$5:$B$1241,MATCH(F6,'Plan de Cuentas'!$A$5:$A$1241,0)),"No encontrado"))
E7: =IF(D7="","",IFERROR(INDEX('Plan de Cuentas'!$B$5:$B$1241,MATCH(D7,'Plan de Cuentas'!$A$5:$A$1241,0)),"No encontrado")) | G7: =IF(F7="","",IFERROR(INDEX('Plan de Cuentas'!$B$5:$B$1241,MATCH(F7,'Plan de Cuentas'!$A$5:$A$1241,0)),"No encontrado"))
E8: =IF(D8="","",IFERROR(INDEX('Plan de Cuentas'!$B$5:$B$1241,MATCH(D8,'Plan de Cuentas'!$A$5:$A$1241,0)),"No encontrado")) | G8: =IF(F8="","",IFERROR(INDEX('Plan de Cuentas'!$B$5:$B$1241,MATCH(F8,'Plan de Cuentas'!$A$5:$A$1241,0)),"No encontrado"))
E9: =IF(D9="","",IFERROR(INDEX('Plan de Cuentas'!$B$5:$B$1241,MATCH(D9,'Plan de Cuentas'!$A$5:$A$1241,0)),"No encontrado")) | G9: =IF(F9="","",IFERROR(INDEX('Plan de Cuentas'!$B$5:$B$1241,MATCH(F9,'Plan de Cuentas'!$A$5:$A$1241,0)),"No encontrado"))
E10: =IF(D10="","",IFERROR(INDEX('Plan de Cuentas'!$B$5:$B$1241,MATCH(D10,'Plan de Cuentas'!$A$5:$A$1241,0)),"No encontrado")) | G10: =IF(F10="","",IFERROR(INDEX('Plan de Cuentas'!$B$5:$B$1241,MATCH(F10,'Plan de Cuentas'!$A$5:$A$1241,0)),"No encontrado"))
E11: =IF(D11="","",IFERROR(INDEX('Plan de Cuentas'!$B$5:$B$1241,MATCH(D11,'Plan de Cuentas'!$A$5:$A$1241,0)),"No encontrado")) | G11: =IF(F11="","",IFERROR(INDEX('Plan de Cuentas'!$B$5:$B$1241,MATCH(F11,'Plan de Cuentas'!$A$5:$A$1241,0)),"No encontrado"))
E12: =IF(D12="","",IFERROR(INDEX('Plan de Cuentas'!$B$5:$B$1241,MATCH(D12,'Plan de Cuentas'!$A$5:$A$1241,0)),"No encontrado")) | G12: =IF(F12="","",IFERROR(INDEX('Plan de Cuentas'!$B$5:$B$1241,MATCH(F12,'Plan de Cuentas'!$A$5:$A$1241,0)),"No encontrado"))
E13: =IF(D13="","",IFERROR(INDEX('Plan de Cuentas'!$B$5:$B$1241,MATCH(D13,'Plan de Cuentas'!$A$5:$A$1241,0)),"No encontrado")) | G13: =IF(F13="","",IFERROR(INDEX('Plan de Cuentas'!$B$5:$B$1241,MATCH(F13,'Plan de Cuentas'!$A$5:$A$1241,0)),"No encontrado"))
E14: =IF(D14="","",IFERROR(INDEX('Plan de Cuentas'!$B$5:$B$1241,MATCH(D14,'Plan de Cuentas'!$A$5:$A$1241,0)),"No encontrado")) | G14: =IF(F14="","",IFERROR(INDEX('Plan de Cuentas'!$B$5:$B$1241,MATCH(F14,'Plan de Cuentas'!$A$5:$A$1241,0)),"No encontrado"))
E15: =IF(D15="","",IFERROR(INDEX('Plan de Cuentas'!$B$5:$B$1241,MATCH(D15,'Plan de Cuentas'!$A$5:$A$1241,0)),"No encontrado")) | G15: =IF(F15="","",IFERROR(INDEX('Plan de Cuentas'!$B$5:$B$1241,MATCH(F15,'Plan de Cuentas'!$A$5:$A$1241,0)),"No encontrado"))
E16: =IF(D16="","",IFERROR(INDEX('Plan de Cuentas'!$B$5:$B$1241,MATCH(D16,'Plan de Cuentas'!$A$5:$A$1241,0)),"No encontrado")) | G16: =IF(F16="","",IFERROR(INDEX('Plan de Cuentas'!$B$5:$B$1241,MATCH(F16,'Plan de Cuentas'!$A$5:$A$1241,0)),"No encontrado"))
E17: =IF(D17="","",IFERROR(INDEX('Plan de Cuentas'!$B$5:$B$1241,MATCH(D17,'Plan de Cuentas'!$A$5:$A$1241,0)),"No encontrado")) | G17: =IF(F17="","",IFERROR(INDEX('Plan de Cuentas'!$B$5:$B$1241,MATCH(F17,'Plan de Cuentas'!$A$5:$A$1241,0)),"No encontrado"))
... E1004: =IF(D1004="","",IFERROR(INDEX('Plan de Cuentas'!$B$5:$B$1241,MATCH(D1004,'Plan de Cuentas'!$A$5:$A$1241,0)),"No encontrado")) | G1004: =IF(F1004="","",IFERROR(INDEX('Plan de Cuentas'!$B$5:$B$1241,MATCH(F1004,'Plan de Cuentas'!$A$5:$A$1241,0)),"No encontrado"))

Sheet Libro Diario
A1: LIBRO DIARIO
A2: Registre aquí cada operación: una fila por cada cuenta que interviene (Debe o Haber). Todo asiento debe tener Debe = Haber. La Denominación se completa sola al escribir el Código (seleccione de la lista desplegable). Ejemplo ya cargado: aporte de capital en efectivo S/ 10.
A4: Fecha | B4: N° Asiento | C4: Código | D4: Denominación | E4: Glosa / Descripción | F4: Debe (S/) | G4: Haber (S/)
A5: 46024 | B5: 1 | C5: 101 | D5: =IF(C5="","",IFERROR(INDEX('Plan de Cuentas'!$B$5:$B$1241,MATCH(C5,'Plan de Cuentas'!$A$5:$A$1241,0)),"Código no encontrado")) -> Caja | E5: Aporte de capital en efectivo - Caja | F5: 10
A6: 46024 | B6: 1 | C6: 5011 | D6: =IF(C6="","",IFERROR(INDEX('Plan de Cuentas'!$B$5:$B$1241,MATCH(C6,'Plan de Cuentas'!$A$5:$A$1241,0)),"Código no encontrado")) -> Acciones | E6: Aporte de capital en efectivo - Capital social (acciones) | G6: 10
D9: =IF(C9="","",IFERROR(INDEX('Plan de Cuentas'!$B$5:$B$1241,MATCH(C9,'Plan de Cuentas'!$A$5:$A$1241,0)),"Código no encontrado"))
D10: =IF(C10="","",IFERROR(INDEX('Plan de Cuentas'!$B$5:$B$1241,MATCH(C10,'Plan de Cuentas'!$A$5:$A$1241,0)),"Código no encontrado"))
D11: =IF(C11="","",IFERROR(INDEX('Plan de Cuentas'!$B$5:$B$1241,MATCH(C11,'Plan de Cuentas'!$A$5:$A$1241,0)),"Código no encontrado"))
D12: =IF(C12="","",IFERROR(INDEX('Plan de Cuentas'!$B$5:$B$1241,MATCH(C12,'Plan de Cuentas'!$A$5:$A$1241,0)),"Código no encontrado"))
D13: =IF(C13="","",IFERROR(INDEX('Plan de Cuentas'!$B$5:$B$1241,MATCH(C13,'Plan de Cuentas'!$A$5:$A$1241,0)),"Código no encontrado"))
D14: =IF(C14="","",IFERROR(INDEX('Plan de Cuentas'!$B$5:$B$1241,MATCH(C14,'Plan de Cuentas'!$A$5:$A$1241,0)),"Código no encontrado"))
D15: =IF(C15="","",IFERROR(INDEX('Plan de Cuentas'!$B$5:$B$1241,MATCH(C15,'Plan de Cuentas'!$A$5:$A$1241,0)),"Código no encontrado"))
D16: =IF(C16="","",IFERROR(INDEX('Plan de Cuentas'!$B$5:$B$1241,MATCH(C16,'Plan de Cuentas'!$A$5:$A$1241,0)),"Código no encontrado"))
D17: =IF(C17="","",IFERROR(INDEX('Plan de Cuentas'!$B$5:$B$1241,MATCH(C17,'Plan de Cuentas'!$A$5:$A$1241,0)),"Código no encontrado"))
D18: =IF(C18="","",IFERROR(INDEX('Plan de Cuentas'!$B$5:$B$1241,MATCH(C18,'Plan de Cuentas'!$A$5:$A$1241,0)),"Código no encontrado"))
D19: =IF(C19="","",IFERROR(INDEX('Plan de Cuentas'!$B$5:$B$1241,MATCH(C19,'Plan de Cuentas'!$A$5:$A$1241,0)),"Código no encontrado"))
D20: =IF(C20="","",IFERROR(INDEX('Plan de Cuentas'!$B$5:$B$1241,MATCH(C20,'Plan de Cuentas'!$A$5:$A$1241,0)),"Código no encontrado"))
... D504: =IF(C504="","",IFERROR(INDEX('Plan de Cuentas'!$B$5:$B$1241,MATCH(C504,'Plan de Cuentas'!$A$5:$A$1241,0)),"Código no encontrado"))
E506: TOTALES (deben ser iguales) | F506: =SUM(F5:F504) -> 10 | G506: =SUM(G5:G504) -> 10
E507: Diferencia (debe ser 0): | F507: =F506-G506 -> 0

Sheet Balance de Comprobación
A1: BALANCE DE COMPROBACIÓN
A2: Se genera automáticamente a partir del Libro Diario: suma los movimientos de cada cuenta del Plan de Cuentas. No requiere edición manual.
A4: Código | B4: Denominación | C4: Elemento | D4: Debe (S/) | E4: Haber (S/) | F4: Saldo Deudor (S/) | G4: Saldo Acreedor (S/)
A5: 101 | B5: Caja | C5: 1 | D5: =SUMIF('Libro Diario'!$C$5:$C$504,A5,'Libro Diario'!$F$5:$F$504) -> 10 | E5: =SUMIF('Libro Diario'!$C$5:$C$504,A5,'Libro Diario'!$G$5:$G$504) -> 0 | F5: =IF(D5>=E5,D5-E5,0) -> 10 | G5: =IF(E5>D5,E5-D5,0) -> 0
A6: 102 | B6: Fondos fijos | C6: 1 | D6: =SUMIF('Libro Diario'!$C$5:$C$504,A6,'Libro Diario'!$F$5:$F$504) -> 0 | E6: =SUMIF('Libro Diario'!$C$5:$C$504,A6,'Libro Diario'!$G$5:$G$504) -> 0 | F6: =IF(D6>=E6,D6-E6,0) -> 0 | G6: =IF(E6>D6,E6-D6,0) -> 0
A7: 1031 | B7: Efectivo en tránsito | C7: 1 | D7: =SUMIF('Libro Diario'!$C$5:$C$504,A7,'Libro Diario'!$F$5:$F$504) -> 0 | E7: =SUMIF('Libro Diario'!$C$5:$C$504,A7,'Libro Diario'!$G$5:$G$504) -> 0 | F7: =IF(D7>=E7,D7-E7,0) -> 0 | G7: =IF(E7>D7,E7-D7,0) -> 0
A8: 1032 | B8: Cheques en tránsito | C8: 1 | D8: =SUMIF('Libro Diario'!$C$5:$C$504,A8,'Libro Diario'!$F$5:$F$504) -> 0 | E8: =SUMIF('Libro Diario'!$C$5:$C$504,A8,'Libro Diario'!$G$5:$G$504) -> 0 | F8: =IF(D8>=E8,D8-E8,0) -> 0 | G8: =IF(E8>D8,E8-D8,0) -> 0
A9: 1041 | B9: Cuentas corrientes operativas | C9: 1 | D9: =SUMIF('Libro Diario'!$C$5:$C$504,A9,'Libro Diario'!$F$5:$F$504) -> 0 | E9: =SUMIF('Libro Diario'!$C$5:$C$504,A9,'Libro Diario'!$G$5:$G$504) -> 0 | F9: =IF(D9>=E9,D9-E9,0) -> 0 | G9: =IF(E9>D9,E9-D9,0) -> 0
A10: 1042 | B10: Cuentas corrientes para fines específicos | C10: 1 | D10: =SUMIF('Libro Diario'!$C$5:$C$504,A10,'Libro Diario'!$F$5:$F$504) -> 0 | E10: =SUMIF('Libro Diario'!$C$5:$C$504,A10,'Libro Diario'!$G$5:$G$504) -> 0 | F10: =IF(D10>=E10,D10-E10,0) -> 0 | G10: =IF(E10>D10,E10-D10,0) -> 0
A11: 1051 | B11: Otro equivalentes de efectivo | C11: 1 | D11: =SUMIF('Libro Diario'!$C$5:$C$504,A11,'Libro Diario'!$F$5:$F$504) -> 0 | E11: =SUMIF('Libro Diario'!$C$5:$C$504,A11,'Libro Diario'!$G$5:$G$504) -> 0 | F11: =IF(D11>=E11,D11-E11,0) -> 0 | G11: =IF(E11>D11,E11-D11,0) -> 0
A12: 1061 | B12: Depósitos de ahorro | C12: 1 | D12: =SUMIF('Libro Diario'!$C$5:$C$504,A12,'Libro Diario'!$F$5:$F$504) -> 0 | E12: =SUMIF('Libro Diario'!$C$5:$C$504,A12,'Libro Diario'!$G$5:$G$504) -> 0 | F12: =IF(D12>=E12,D12-E12,0) -> 0 | G12: =IF(E12>D12,E12-D12,0) -> 0
A13: 1062 | B13: Depósitos a plazo | C13: 1 | D13: =SUMIF('Libro Diario'!$C$5:$C$504,A13,'Libro Diario'!$F$5:$F$504) -> 0 | E13: =SUMIF('Libro Diario'!$C$5:$C$504,A13,'Libro Diario'!$G$5:$G$504) -> 0 | F13: =IF(D13>=E13,D13-E13,0) -> 0 | G13: =IF(E13>D13,E13-D13,0) -> 0
A14: 1071 | B14: Fondos en garantía | C14: 1 | D14: =SUMIF('Libro Diario'!$C$5:$C$504,A14,'Libro Diario'!$F$5:$F$504) -> 0 | E14: =SUMIF('Libro Diario'!$C$5:$C$504,A14,'Libro Diario'!$G$5:$G$504) -> 0 | F14: =IF(D14>=E14,D14-E14,0) -> 0 | G14: =IF(E14>D14,E14-D14,0) -> 0
A15: 1072 | B15: Fondos retenidos por mandato de la autoridad | C15: 1 | D15: =SUMIF('Libro Diario'!$C$5:$C$504,A15,'Libro Diario'!$F$5:$F$504) -> 0 | E15: =SUMIF('Libro Diario'!$C$5:$C$504,A15,'Libro Diario'!$G$5:$G$504) -> 0 | F15: =IF(D15>=E15,D15-E15,0) -> 0 | G15: =IF(E15>D15,E15-D15,0) -> 0
A16: 1073 | B16: Otros fondos sujetos a restricción | C16: 1 | D16: =SUMIF('Libro Diario'!$C$5:$C$504,A16,'Libro Diario'!$F$5:$F$504) -> 0 | E16: =SUMIF('Libro Diario'!$C$5:$C$504,A16,'Libro Diario'!$G$5:$G$504) -> 0 | F16: =IF(D16>=E16,D16-E16,0) -> 0 | G16: =IF(E16>D16,E16-D16,0) -> 0
... A1241: 97 | B1241: Gastos Financieros | C1241: 9 | D1241: =SUMIF('Libro Diario'!$C$5:$C$504,A1241,'Libro Diario'!$F$5:$F$504) -> 0 | E1241: =SUMIF('Libro Diario'!$C$5:$C$504,A1241,'Libro Diario'!$G$5:$G$504) -> 0 | F1241: =IF(D1241>=E1241,D1241-E1241,0) -> 0 | G1241: =IF(E1241>D1241,E1241-D1241,0) -> 0
B1242: TOTAL | D1242: =SUM(D5:D1241) -> 10 | E1242: =SUM(E5:E1241) -> 10 | F1242: =SUM(F5:F1241) -> 10 | G1242: =SUM(G5:G1241) -> 10

Sheet Estado de Resultados
A1: ESTADO DE RESULTADOS (por naturaleza)
A2: Se calcula automáticamente a partir del Balance de Comprobación (elementos 6 y 7 del PCGE). Solo complete la celda amarilla del Impuesto a la Renta.
A4: INGRESOS DE ACTIVIDADES ORDINARIAS
A5: 70 Ventas | B5: =(SUMIFS('Balance de Comprobación'!$G$5:$G$1241,'Balance de Comprobación'!$A$5:$A$1241,"70*")-SUMIFS('Balance de Comprobación'!$F$5:$F$1241,'Balance de Comprobación'!$A$5:$A$1241,"70*")) -> 0
A6: (-) 74 Descuentos, rebajas y bonificaciones concedidas | B6: =-(SUMIFS('Balance de Comprobación'!$F$5:$F$1241,'Balance de Comprobación'!$A$5:$A$1241,"74*")-SUMIFS('Balance de Comprobación'!$G$5:$G$1241,'Balance de Comprobación'!$A$5:$A$1241,"74*")) -> 0
A7: Ventas netas | B7: =B5+B6 -> 0
A8: 73 Descuentos, rebajas y bonificaciones obtenidas | B8: =(SUMIFS('Balance de Comprobación'!$G$5:$G$1241,'Balance de Comprobación'!$A$5:$A$1241,"73*")-SUMIFS('Balance de Comprobación'!$F$5:$F$1241,'Balance de Comprobación'!$A$5:$A$1241,"73*")) -> 0
A9: 75 Otros ingresos de gestión | B9: =(SUMIFS('Balance de Comprobación'!$G$5:$G$1241,'Balance de Comprobación'!$A$5:$A$1241,"75*")-SUMIFS('Balance de Comprobación'!$F$5:$F$1241,'Balance de Comprobación'!$A$5:$A$1241,"75*")) -> 0
A10: 71 Variación de la producción almacenada | B10: =(SUMIFS('Balance de Comprobación'!$G$5:$G$1241,'Balance de Comprobación'!$A$5:$A$1241,"71*")-SUMIFS('Balance de Comprobación'!$F$5:$F$1241,'Balance de Comprobación'!$A$5:$A$1241,"71*")) -> 0
A11: 72 Producción de activo inmovilizado | B11: =(SUMIFS('Balance de Comprobación'!$G$5:$G$1241,'Balance de Comprobación'!$A$5:$A$1241,"72*")-SUMIFS('Balance de Comprobación'!$F$5:$F$1241,'Balance de Comprobación'!$A$5:$A$1241,"72*")) -> 0
A12: 76 Ganancia por medición de activos no financieros al valor razonable | B12: =(SUMIFS('Balance de Comprobación'!$G$5:$G$1241,'Balance de Comprobación'!$A$5:$A$1241,"76*")-SUMIFS('Balance de Comprobación'!$F$5:$F$1241,'Balance de Comprobación'!$A$5:$A$1241,"76*")) -> 0
A13: 77 Ingresos financieros | B13: =(SUMIFS('Balance de Comprobación'!$G$5:$G$1241,'Balance de Comprobación'!$A$5:$A$1241,"77*")-SUMIFS('Balance de Comprobación'!$F$5:$F$1241,'Balance de Comprobación'!$A$5:$A$1241,"77*")) -> 0
A14: 78 Cargas cubiertas por provisiones | B14: =(SUMIFS('Balance de Comprobación'!$G$5:$G$1241,'Balance de Comprobación'!$A$5:$A$1241,"78*")-SUMIFS('Balance de Comprobación'!$F$5:$F$1241,'Balance de Comprobación'!$A$5:$A$1241,"78*")) -> 0
A15: TOTAL INGRESOS | B15: =B7+B8+B9+B10+B11+B12+B13+B14 -> 0
A17: GASTOS
A18: 60 Compras | B18: =(SUMIFS('Balance de Comprobación'!$F$5:$F$1241,'Balance de Comprobación'!$A$5:$A$1241,"60*")-SUMIFS('Balance de Comprobación'!$G$5:$G$1241,'Balance de Comprobación'!$A$5:$A$1241,"60*")) -> 0
A19: 61 Variación de existencias | B19: =(SUMIFS('Balance de Comprobación'!$F$5:$F$1241,'Balance de Comprobación'!$A$5:$A$1241,"61*")-SUMIFS('Balance de Comprobación'!$G$5:$G$1241,'Balance de Comprobación'!$A$5:$A$1241,"61*")) -> 0
A20: 62 Gastos de personal, directores y gerentes | B20: =(SUMIFS('Balance de Comprobación'!$F$5:$F$1241,'Balance de Comprobación'!$A$5:$A$1241,"62*")-SUMIFS('Balance de Comprobación'!$G$5:$G$1241,'Balance de Comprobación'!$A$5:$A$1241,"62*")) -> 0
A21: 63 Gastos de servicios prestados por terceros | B21: =(SUMIFS('Balance de Comprobación'!$F$5:$F$1241,'Balance de Comprobación'!$A$5:$A$1241,"63*")-SUMIFS('Balance de Comprobación'!$G$5:$G$1241,'Balance de Comprobación'!$A$5:$A$1241,"63*")) -> 0
A22: 64 Gastos por tributos | B22: =(SUMIFS('Balance de Comprobación'!$F$5:$F$1241,'Balance de Comprobación'!$A$5:$A$1241,"64*")-SUMIFS('Balance de Comprobación'!$G$5:$G$1241,'Balance de Comprobación'!$A$5:$A$1241,"64*")) -> 0
A23: 65 Otros gastos de gestión | B23: =(SUMIFS('Balance de Comprobación'!$F$5:$F$1241,'Balance de Comprobación'!$A$5:$A$1241,"65*")-SUMIFS('Balance de Comprobación'!$G$5:$G$1241,'Balance de Comprobación'!$A$5:$A$1241,"65*")) -> 0
A24: 66 Pérdida por medición de activos no financieros al valor razonable | B24: =(SUMIFS('Balance de Comprobación'!$F$5:$F$1241,'Balance de Comprobación'!$A$5:$A$1241,"66*")-SUMIFS('Balance de Comprobación'!$G$5:$G$1241,'Balance de Comprobación'!$A$5:$A$1241,"66*")) -> 0
A25: 67 Gastos financieros | B25: =(SUMIFS('Balance de Comprobación'!$F$5:$F$1241,'Balance de Comprobación'!$A$5:$A$1241,"67*")-SUMIFS('Balance de Comprobación'!$G$5:$G$1241,'Balance de Comprobación'!$A$5:$A$1241,"67*")) -> 0
A26: 68 Valuación y deterioro de activos y provisiones | B26: =(SUMIFS('Balance de Comprobación'!$F$5:$F$1241,'Balance de Comprobación'!$A$5:$A$1241,"68*")-SUMIFS('Balance de Comprobación'!$G$5:$G$1241,'Balance de Comprobación'!$A$5:$A$1241,"68*")) -> 0
A27: 69 Costo de ventas | B27: =(SUMIFS('Balance de Comprobación'!$F$5:$F$1241,'Balance de Comprobación'!$A$5:$A$1241,"69*")-SUMIFS('Balance de Comprobación'!$G$5:$G$1241,'Balance de Comprobación'!$A$5:$A$1241,"69*")) -> 0
A28: 79 Cargas imputables a cuentas de costos y gastos | B28: =(SUMIFS('Balance de Comprobación'!$F$5:$F$1241,'Balance de Comprobación'!$A$5:$A$1241,"79*")-SUMIFS('Balance de Comprobación'!$G$5:$G$1241,'Balance de Comprobación'!$A$5:$A$1241,"79*")) -> 0
A29: TOTAL GASTOS | B29: =B18+B19+B20+B21+B22+B23+B24+B25+B26+B27+B28 -> 0
A31: RESULTADO ANTES DE IMPUESTO A LA RENTA | B31: =B15-B29 -> 0
A32: Impuesto a la renta (ingréselo manualmente) | B32: 0
A33: RESULTADO NETO DEL EJERCICIO | B33: =B31-B32 -> 0

Sheet Estado de Situación Financiera
A1: ESTADO DE SITUACIÓN FINANCIERA
A2: Se calcula automáticamente a partir del Balance de Comprobación (elementos 1 a 5 del PCGE) y del Estado de Resultados (utilidad o pérdida del ejercicio).
A4: ACTIVO
A5: Elemento 1 - Activo disponible y exigible (10 a 19) | B5: =(SUMIFS('Balance de Comprobación'!$F$5:$F$1241,'Balance de Comprobación'!$A$5:$A$1241,"1*")-SUMIFS('Balance de Comprobación'!$G$5:$G$1241,'Balance de Comprobación'!$A$5:$A$1241,"1*")) -> 10
A6: Elemento 2 - Activo realizable (20 a 29) | B6: =(SUMIFS('Balance de Comprobación'!$F$5:$F$1241,'Balance de Comprobación'!$A$5:$A$1241,"2*")-SUMIFS('Balance de Comprobación'!$G$5:$G$1241,'Balance de Comprobación'!$A$5:$A$1241,"2*")) -> 0
A7: Elemento 3 - Activo inmovilizado (30 a 39) | B7: =(SUMIFS('Balance de Comprobación'!$F$5:$F$1241,'Balance de Comprobación'!$A$5:$A$1241,"3*")-SUMIFS('Balance de Comprobación'!$G$5:$G$1241,'Balance de Comprobación'!$A$5:$A$1241,"3*")) -> 0
A8: TOTAL ACTIVO | B8: =B5+B6+B7 -> 10
A10: PASIVO
A11: Elemento 4 - Pasivo (40 a 49) | B11: =(SUMIFS('Balance de Comprobación'!$G$5:$G$1241,'Balance de Comprobación'!$A$5:$A$1241,"4*")-SUMIFS('Balance de Comprobación'!$F$5:$F$1241,'Balance de Comprobación'!$A$5:$A$1241,"4*")) -> 0
A12: TOTAL PASIVO | B12: =B11 -> 0
A14: PATRIMONIO
A15: Elemento 5 - Patrimonio (50 a 59) | B15: =(SUMIFS('Balance de Comprobación'!$G$5:$G$1241,'Balance de Comprobación'!$A$5:$A$1241,"5*")-SUMIFS('Balance de Comprobación'!$F$5:$F$1241,'Balance de Comprobación'!$A$5:$A$1241,"5*")) -> 10
A16: Resultado del ejercicio (según Estado de Resultados) | B16: ='Estado de Resultados'!$B$33 -> 0
A17: TOTAL PATRIMONIO | B17: =B15+B16 -> 10
A19: TOTAL PASIVO + PATRIMONIO | B19: =B12+B17 -> 10
A20: Diferencia (Activo - Pasivo - Patrimonio; debe ser 0) | B20: =B8-B19 -> 0

Sheet Plan de Cuentas
A1: PLAN DE CUENTAS (PCGE 2019) - Lista para uso en fórmulas
A2: Cuentas de máximo detalle del PCGE 2019. Esta hoja alimenta el Libro Diario y el Balance de Comprobación mediante fórmulas. No la reordene ni borre filas.
A4: Código | B4: Denominación | C4: Elemento | D4: Nombre del Elemento
A5: 101 | B5: Caja | C5: 1 | D5: ACTIVO DISPONIBLE Y EXIGIBLE
A6: 102 | B6: Fondos fijos | C6: 1 | D6: ACTIVO DISPONIBLE Y EXIGIBLE
A7: 1031 | B7: Efectivo en tránsito | C7: 1 | D7: ACTIVO DISPONIBLE Y EXIGIBLE
A8: 1032 | B8: Cheques en tránsito | C8: 1 | D8: ACTIVO DISPONIBLE Y EXIGIBLE
A9: 1041 | B9: Cuentas corrientes operativas | C9: 1 | D9: ACTIVO DISPONIBLE Y EXIGIBLE
A10: 1042 | B10: Cuentas corrientes para fines específicos | C10: 1 | D10: ACTIVO DISPONIBLE Y EXIGIBLE
A11: 1051 | B11: Otro equivalentes de efectivo | C11: 1 | D11: ACTIVO DISPONIBLE Y EXIGIBLE
A12: 1061 | B12: Depósitos de ahorro | C12: 1 | D12: ACTIVO DISPONIBLE Y EXIGIBLE
A13: 1062 | B13: Depósitos a plazo | C13: 1 | D13: ACTIVO DISPONIBLE Y EXIGIBLE
A14: 1071 | B14: Fondos en garantía | C14: 1 | D14: ACTIVO DISPONIBLE Y EXIGIBLE
A15: 1072 | B15: Fondos retenidos por mandato de la autoridad | C15: 1 | D15: ACTIVO DISPONIBLE Y EXIGIBLE
... A1241: 97 | B1241: Gastos Financieros | C1241: 9 | D1241: Contabilidad Analítica De Explotación (Costos Y Gastos Por Función)

Sheet PCGE 2019 (detalle)
A1: PLAN CONTABLE GENERAL EMPRESARIAL (PCGE 2019) - PERÚ
A2: Catálogo completo (Capítulo II del PCGE 2019, Res. CNC). Complete solo las celdas amarillas de la columna Monto (S/), que corresponden a las cuentas de mayor detalle. Use los botones [+/-] del margen izquierdo para expandir o contraer niveles.
A4: Código | B4: Denominación | C4: Monto (S/)
A5: ELEMENTO 1: ACTIVO DISPONIBLE Y EXIGIBLE
A6: 10 | B6: EFECTIVO Y EQUIVALENTES DE EFECTIVO
A7: 101 | B7: Caja | C7: 10
A8: 102 | B8: Fondos fijos
A9: 103 | B9: Efectivo y cheques en tránsito
A10: 1031 | B10: Efectivo en tránsito
A11: 1032 | B11: Cheques en tránsito
A12: 104 | B12: Cuentas corrientes en instituciones financieras
A13: 1041 | B13: Cuentas corrientes operativas
A14: 1042 | B14: Cuentas corrientes para fines específicos
A15: 105 | B15: Otros equivalentes de efectivo
A16: 1051 | B16: Otro equivalentes de efectivo
A17: 106 | B17: Depósitos en instituciones financieras
A18: 1061 | B18: Depósitos de ahorro
A19: 1062 | B19: Depósitos a plazo
... A192: 1959 | B192: Otras cuentas por cobrar diversas
A193: ELEMENTO 2: ACTIVO REALIZABLE
A194: 20 | B194: MERCADERÍAS
A195: 201 | B195: Mercaderías
A196: 2011 | B196: Mercaderías
A197: 20111 | B197: Costo
A198: 20114 | B198: Valor razonable
A199: 21 | B199: PRODUCTOS TERMINADOS
A200: 211 | B200: Productos terminados
A201: 2111 | B201: Productos terminados
A202: 21111 | B202: Costo
A203: 21113 | B203: Costo de financiación
A204: 21114 | B204: Valor razonable
A205: 215 | B205: Inventario de servicios terminados
... A431: 2984 | B431: Envases y embalajes
A432: ELEMENTO 3: ACTIVO INMOVILIZADO
A433: 30 | B433: INVERSIONES MOBILIARIAS
A434: 301 | B434: Inversiones a ser mantenidas hasta el vencimiento
A435: 3011 | B435: Instrumentos financieros representativos de deuda
A436: 30221 | B436: Costo
A437: 30224 | B437: Valor razonable
A438: 302 | B438: Instrumentos financieros representativos de derecho patrimonial
...

Sheet Instrucciones Macro
A1: CÓMO ACTIVAR EL REGISTRO AUTOMÁTICO (1 sola vez, ~2 minutos)
A2: Excel no permite que un botón 'registre datos solo' sin una macro (VBA). Este es un procedimiento estándar y seguro: usted mismo pega el código, así que sabe exactamente qué hace (ver abajo). Una vez hecho, quedará guardado en el archivo para siempre.
A4: 1. Guarde este archivo como .xlsm: Archivo > Guardar como > tipo 'Libro de Excel habilitado para macros (*.xlsm)'.
A5: 2. Active la pestaña Programador si no la ve: Archivo > Opciones > Personalizar cinta > marque 'Programador'.
A6: 3. Presione Alt+F11 para abrir el editor de VBA. Clic derecho en el nombre del archivo (VBAProject) > Insertar > Módulo.
A7: 4. Copie y pegue todo el código de más abajo (o del archivo RegistrarIngreso.bas adjunto) en ese módulo.
A8: 5. Cierre el editor de VBA (Alt+Q). Vuelva a la hoja 'Formulario de Ingreso'.
A9: 6. Pestaña Programador > Insertar > Botón (control de formulario). Dibújelo sobre el recuadro verde 'REGISTRAR INGRESO'.
A10: 7. En la ventana que aparece, seleccione la macro 'RegistrarIngreso' y presione Aceptar.
A11: 8. Guarde el archivo. Cada vez que llene el formulario y presione el botón, se guardará solo en 'Base de Datos' y en 'Libro Diario'.
A13: Código de la macro (también está en el archivo RegistrarIngreso.bas):
A14: Option Explicit Sub RegistrarIngreso() Dim wsForm As Worksheet, wsBD As Worksheet, wsDiario As Worksheet Dim cuenta As String, contra As String, obs As String, tipo As String Dim monto As Double Dim filaBD As Long, filaDiario As Long, nRegistro As Long Dim fechaHoy As Date, horaAhora As Date Set wsForm = ThisWorkbook.Sheets("Formulario de Ingreso") Set wsBD = ThisWorkbook.Sheets("Base de Datos") Set wsDiario = ThisWorkbook.Sheets("Libro Diario") cuenta = Trim(wsForm.Range("C6").Value) contra = Trim(wsForm.Range("C7").Value) monto = wsForm.Range("C8").Value obs = Trim(wsForm.Range("C9").Value) tipo = Trim(wsForm.Range("C10").Value) ' --- Validaciones minimas --- If cuenta = "" Or contra = "" Or monto <= 0 Or tipo = "" Then MsgBox "Complete Cuenta, Contra-cuenta, Monto (mayor a 0) y Tipo de movimiento antes de registrar.", vbExclamation Exit Sub End If If IsError(Application.Match(cuenta, ThisWorkbook.Sheets("Plan de Cuentas").Range("A5:A1241"), 0)) Then MsgBox "El código de Cuenta '" & cuenta & "' no existe en el Plan de Cuentas.", vbExclamation Exit Sub End If If IsError(Application.Match(contra, ThisWorkbook.Sheets("Plan de Cuentas").Range("A5:A1241"), 0)) Then MsgBox "El código de Contra-cuenta '" & contra & "' no existe en el Plan de Cuentas.", vbExclamation Exit Sub End If fechaHoy = Date horaAhora = Time ' --- 1) Escribir en Base de Datos (siguiente fila libre desde la fila 5) --- filaBD = 5 Do While wsBD.Cells(filaBD, 1).Value <> "" filaBD = filaBD + 1 Loop nRegistro = wsBD.Cells(filaBD - 1, 1).Value + 1 If filaBD = 5 Then nRegistro = 1 wsBD.Cells(filaBD, 1).Value = nRegistro ' N° wsBD.Cells(filaBD, 2).Value = fechaHoy ' Fecha wsBD.Cells(filaBD, 3).Value = horaAhora ' Hora wsBD.Cells(filaBD, 4).Value = cuenta ' Codigo cuenta wsBD.Cells(filaBD, 6).Value = contra ' Codigo contra-cuenta wsBD.Cells(filaBD, 8).Value = monto ' Monto wsBD.Cells(filaBD, 9).Value = obs ' Observacion ' Las columnas E y G (denominaciones) ya tienen formula propia en cada fila ' --- 2) Escribir en Libro Diario (dos filas: Debe y Haber) --- filaDiario = 5 Do While wsDiario.Cells(filaDiario, 3).Value <> "" And filaDiario <= 504 filaDiario = filaDiario + 1 Loop If filaDiario > 503 Then MsgBox "El Libro Diario llegó a su límite de filas provisionadas (500). Avísame para ampliarlo.", vbCritical Exit Sub End If Dim esDebeCuentaPrincipal As Boolean esDebeCuentaPrincipal = (InStr(tipo, "Debe") > 0) ' Fila 1 del asiento: cuenta principal wsDiario.Cells(filaDiario, 1).Value = fechaHoy wsDiario.Cells(filaDiario, 2).Value = nRegistro wsDiario.Cells(filaDiario, 3).Value = cuenta wsDiario.Cells(filaDiario, 5).Value = obs If esDebeCuentaPrincipal Then wsDiario.Cells(filaDiario, 6).Value = monto Else wsDiario.Cells(filaDiario, 7).Value = monto End If ' Fila 2 del asiento: contra-cuenta (con el signo contrario) wsDiario.Cells(filaDiario + 1, 1).Value = fechaHoy wsDiario.Cells(filaDiario + 1, 2).Value = nRegistro wsDiario.Cells(filaDiario + 1, 3).Value = contra wsDiario.Cells(filaDiario + 1, 5).Value = obs If esDebeCuentaPrincipal Then wsDiario.Cells(filaDiario + 1, 7).Value = monto Else wsDiario.Cells(filaDiario + 1, 6).Value = monto End If ' --- 3) Limpiar el formulario para el siguiente registro --- wsForm.Range("C6").Value = "" wsForm.Range("C7").Value = "" wsForm.Range("C8").Value = "" wsForm.Range("C9").Value = "" wsForm.Range("C10").Value = "" Application.Calculate MsgBox "Registro N° " & nRegistro & " guardado en Base de Datos y en el Libro Diario.", vbInformation End Sub
